Workbook
Name clients: [1]!liste_clients[[#All],[SELECTIONNER LE CLIENT]]
Name clients: [1]!liste_clients[[#All],[SELECTIONNER LE CLIENT]]
Name l_clients: [1]liste_clients!$A:$A

Sheet LISTE CATEGORIE
E2: catalogue avec + 10 cts
D3: Catalogue Amiratex PR
B5: CODE | C5: REFERENCE | D5: DESCRITION | E5: poids par balle | F5: nbre de balles | G5: POIDS TOTAL | H5: PRIX | I5: TOTAL | J5: Colonne1
D6: CREME + GRADE A ÉTÉ
B7: 5000 | C7: M.C.P | D7: Pantalon en coton pour homme | E7: 40 | F7: 5 | G7: =E7*F7 -> 200 | H7: 1.6 | I7: =G7*H7 -> 320 | J7: ok | K7: =H7-0.1 -> 1.5 | M7: Bonjour M.Sabir,
B8: 5001 | C8: M.I.P | D8: Pantalon Jeans Homme | E8: 65 | F8: 6 | G8: =E8*F8 -> 390 | H8: 1.6 | I8: =G8*H8 -> 624 | J8: ok | K8: =H8-0.1 -> 1.5 | M8: J’espère que vous allez bien j’ai bien reçu votre catalogue et je tiens à vous remerciez , après avoir bien réfléchir :
B9: 5002 | C9: M.TR.P | D9: Pantalon Tergal Homme | E9: 40 | F9: 5 | G9: =E9*F9 -> 200 | H9: 2 | I9: =G9*H9 -> 400 | J9: ok | K9: =H9-0.1 -> 1.9 | L9: =LEFT(M9,4) -> 5062 | M9: 5062 (Jupe +robe en coton pour fille ) | P9: =VLOOKUP(L9,B7:I110,E7:E110,FALSE) -> #N/A
B10: 5003 | C10: L.M.P | D10: Pantalon mixte femme | E10: 40 | F10: 35 | G10: =E10*F10 -> 1400 | H10: 1.6 | I10: =G10*H10 -> 2240 | K10: =H10-0.1 -> 1.5 | L10: =LEFT(M10,4) -> 5052 | M10: 5052 (Short original enfant )
B11: 5006 | C11: VIZOON | D11: Vizoon + Femme + Enfants+ leggings | E11: 45 | F11: 10 | G11: =E11*F11 -> 450 | H11: 1.6 | I11: =G11*H11 -> 720 | K11: =H11-0.1 -> 1.5 | L11: =LEFT(M11,4) -> 5000 | M11: 5000 (Pantalon en coton pour homme )
B12: 5007 | C12: B.M.P | D12: Pantalon Mixte Garçon | E12: 40 | F12: 15 | G12: =E12*F12 -> 600 | H12: 1.6 | I12: =G12*H12 -> 960 | J12: ok | K12: =H12-0.1 -> 1.5 | L12: =LEFT(M12,4) -> 5002 | M12: 5002 (Pantalon Tergal homme )
B13: 5008 | C13: CH.P | D13: Pantalons enfants | E13: 40 | F13: 3 | G13: =E13*F13 -> 120 | H13: 1.6 | I13: =G13*H13 -> 192 | K13: =H13-0.1 -> 1.5 | L13: =LEFT(M13,4) -> 5020 | M13: 5020 (Chemises en coton pour hommes )
B14: 5009 | C14: T.T | D14: vêtements de travail | E14: 55 | F14: 8 | G14: =E14*F14 -> 440 | H14: 1.3 | I14: =G14*H14 -> 572 | K14: =H14-0.1 -> 1.2 | L14: =LEFT(M14,4) -> 5017 | M14: 5017 (Robe de nuit pour femmes )
B15: 5010 | C15: C.C.R MIX | D15: Short et rummage enfants | E15: 45 | F15: 15 | G15: =E15*F15 -> 675 | H15: 3 | I15: =G15*H15 -> 2025 | J15: ok | K15: =H15-0.1 -> 2.9 | L15: =LEFT(M15,4) -> 5025 | M15: 5025 (Chemise enfant )
B16: 5011 | C16: N.R | D16: Rummages nylon | E16: 45 | F16: 4 | G16: =E16*F16 -> 180 | H16: 1.6 | I16: =G16*H16 -> 288 | J16: ok | K16: =H16-0.1 -> 1.5 | L16: =LEFT(M16,4) -> 5090 | M16: 5090 (Sacs à main )
B17: 5012 | C17: MAYO | D17: Mayo | E17: 40 | F17: 10 | G17: =E17*F17 -> 400 | H17: 1.6 | I17: =G17*H17 -> 640 | K17: =H17-0.1 -> 1.5 | L17: =LEFT(M17,4) -> 5010 | M17: 5010 (Short et rummage enfants )
B18: 5013 | C18: U.W | D18: Sous-vêtements Femme | E18: 40 | F18: 2 | G18: =E18*F18 -> 80 | H18: 1.6 | I18: =G18*H18 -> 128 | J18: ok | K18: =H18-0.1 -> 1.5 | L18: =LEFT(M18,4) -> 5058 | M18: 5058 (Pantalon femme Hawaï )
B19: 5014 | C19: U.W | D19: Sous-vêtements | E19: 55 | F19: 4 | G19: =E19*F19 -> 220 | H19: 1.6 | I19: =G19*H19 -> 352 | K19: =H19-0.1 -> 1.5 | L19: =LEFT(M19,4) -> 5096 | M19: 5096 (T-shirt homme )
B20: 5015 | C20: B.H | D20: brassière | E20: 80 | F20: 3 | G20: =E20*F20 -> 240 | H20: 1.6 | I20: =G20*H20 -> 384 | K20: =H20-0.1 -> 1.5 | L20: =LEFT(M20,4) -> 5097 | M20: 5097 (T-shirt Femme )
B21: 5017 | C21: L.N.DR | D21: Robes de nuit pour femmes | E21: 45 | F21: 1 | G21: =E21*F21 -> 45 | H21: 1.6 | I21: =G21*H21 -> 72 | K21: =H21-0.1 -> 1.5 | L21: =LEFT(M21,4) -> 337 | M21: 337 (Polo Garçon )
B22: 5018 | C22: SKA | D22: Écharpes | E22: 40 | F22: 10 | G22: =E22*F22 -> 400 | H22: 1.6 | I22: =G22*H22 -> 640 | J22: ok | K22: =H22-0.1 -> 1.5 | L22: =LEFT(M22,4) -> 360 | M22: 360 (Robe en coton pour femme )
B23: 5020 | C23: M.C.SH | D23: Chemises en coton pour hommes | E23: 40 | F23: 3 | G23: =E23*F23 -> 120 | H23: 3 | I23: =G23*H23 -> 360 | J23: ok | K23: =H23-0.1 -> 2.9 | L23: =LEFT(M23,4) -> 5118 | M23: 5118 (Robe de soirée )
B24: 5024 | C24: L.S.BL | D24: Chemisier en soie Femme | E24: 40 | F24: 5 | G24: =E24*F24 -> 200 | H24: 1.6 | I24: =G24*H24 -> 320 | K24: =H24-0.1 -> 1.5 | L24: =LEFT(M24,4) -> 870 | M24: 870 (Bijoux
B25: 5025 | C25: B.C.SH | D25: Chemise Enfant | E25: 80 | F25: 1 | G25: =E25*F25 -> 80 | H25: 1.3 | I25: =G25*H25 -> 104 | J25: ok | K25: =H25-0.1 -> 1.2 | L25: =LEFT(M25,4) -> 5007 | M25: 5007 (Pantalon mixte Garçon )
B26: 5026 | C26: G.C.BL | D26: Blouse en coton fille | E26: 40 | F26: 14 | G26: =E26*F26 -> 560 | H26: 1.6 | I26: =G26*H26 -> 896 | K26: =H26-0.1 -> 1.5 | L26: =LEFT(M26,4) -> 5006 | M26: 5006 (Vizon +Femme + enfant +legging )
B27: 5027 | C27: B.T-SHIRT | D27: T-Shirt enfant | E27: 40 | F27: 5 | G27: =E27*F27 -> 200 | H27: 2 | I27: =G27*H27 -> 400 | J27: ok | K27: =H27-0.1 -> 1.9 | L27: =LEFT(M27,4) -> 5122 | M27: 5122 (Chemise femme coton et soie)
B28: 5036 | C28: BODY SWEAT | D28: Body Sweat | E28: 55 | F28: 2 | G28: =E28*F28 -> 110 | H28: 2 | I28: =G28*H28 -> 220 | K28: =H28-0.1 -> 1.9 | L28: =LEFT(M28,4) -> 303 | M28: 303 (Pantalon mixte dame )
B29: 5039 | C29: BODY SIS | D29: Body À Manches Courtes | E29: 45 | F29: 10 | G29: =E29*F29 -> 450 | H29: 1.6 | I29: =G29*H29 -> 720 | K29: =H29-0.1 -> 1.5
B30: 5040 | C30: T.S | D30: Jogging haut et bas | E30: 45 | F30: 10 | G30: =E30*F30 -> 450 | H30: 1.6 | I30: =G30*H30 -> 720 | J30: ok | K30: =H30-0.1 -> 1.5
B31: 5041 | C31: CH.T.S | D31: Jogging enfant | E31: 40 | F31: 6 | G31: =E31*F31 -> 240 | H31: 1.6 | I31: =G31*H31 -> 384 | J31: ok | K31: =H31-0.1 -> 1.5
B32: 5043 | C32: JOGGING | D32: Jogging | E32: 40 | F32: 4 | G32: =E32*F32 -> 160 | H32: 1.6 | I32: =G32*H32 -> 256 | K32: =H32-0.1 -> 1.5
B33: 5051 | C33: L.O.SH | D33: Short Original Femme | E33: 45 | F33: 1 | G33: =E33*F33 -> 45 | H33: 1.6 | I33: =G33*H33 -> 72 | J33: ok | K33: =H33-0.1 -> 1.5
B34: 5052 | C34: B.O.SH | D34: Short Original Enfants | E34: 45 | F34: 5 | G34: =E34*F34 -> 225 | H34: 1.6 | I34: =G34*H34 -> 360 | J34: ok | K34: =H34-0.1 -> 1.5
B35: 5057 | C35: M.O.SH | D35: Short Original Homme | E35: 40 | F35: 2 | G35: =E35*F35 -> 80 | H35: 2 | I35: =G35*H35 -> 160 | J35: ok | K35: =H35-0.1 -> 1.9
B36: 5058 | C36: L.HAWA 1.P | D36: Pantalon Femme hawai | E36: 55 | F36: 2 | G36: =E36*F36 -> 110 | H36: 3 | I36: =G36*H36 -> 330 | K36: =H36-0.1 -> 2.9
B37: 5060 | C37: L.C.DR | D37: Robe en coton pour femme | E37: 40 | F37: 15 | G37: =E37*F37 -> 600 | H37: 3 | I37: =G37*H37 -> 1800 | K37: =H37-0.1 -> 2.9
B38: 5061 | C38: L.C.SK | D38: Jupe en coton femme | E38: 80 | F38: 5 | G38: =E38*F38 -> 400 | H38: 1.3 | I38: =G38*H38 -> 520 | K38: =H38-0.1 -> 1.2
B39: 5062 | C39: G.C.SK+DR | D39: Jupes + robes en coton pour fille | E39: 45 | F39: 15 | G39: =E39*F39 -> 675 | H39: 1.6 | I39: =G39*H39 -> 1080 | K39: =H39-0.1 -> 1.5
B40: 5070 | C40: H.H.R | D40: Rummages maison | E40: 40 | F40: 70 | G40: =E40*F40 -> 2800 | H40: 1.6 | I40: =G40*H40 -> 4480 | J40: ok | K40: =H40-0.1 -> 1.5
B41: 5073 | C41: COVERLY | D41: Coverly | E41: 55 | F41: 5 | G41: =E41*F41 -> 275 | H41: 1.6 | I41: =G41*H41 -> 440 | J41: ok | K41: =H41-0.1 -> 1.5
B42: 5074 | C42: BLA | D42: Couverture | E42: 40 | F42: 12 | G42: =E42*F42 -> 480 | H42: 1.6 | I42: =G42*H42 -> 768 | J42: ok | K42: =H42-0.1 -> 1.5
...

Sheet Feuil5
A4: 5062 | B4: =VLOOKUP(A4,Tableau1[],'LISTE CATEGORIE'!E:E,FALSE) -> #N/A
A5: 5052 | B5: =VLOOKUP(A5,Tableau1[],'LISTE CATEGORIE'!E:E,FALSE) -> #N/A
A6: 5000 | B6: =VLOOKUP(A6,Tableau1[],'LISTE CATEGORIE'!E:E,FALSE) -> #N/A
A7: 5002 | B7: =VLOOKUP(A7,Tableau1[],'LISTE CATEGORIE'!E:E,FALSE) -> #N/A
A8: 5020 | B8: =VLOOKUP(A8,Tableau1[],'LISTE CATEGORIE'!E:E,FALSE) -> #N/A
A9: 5017 | B9: =VLOOKUP(A9,Tableau1[],'LISTE CATEGORIE'!E:E,FALSE) -> #N/A
A10: 5025 | B10: =VLOOKUP(A10,Tableau1[],'LISTE CATEGORIE'!E:E,FALSE) -> #N/A
A11: 5090 | B11: =VLOOKUP(A11,Tableau1[],'LISTE CATEGORIE'!E:E,FALSE) -> #N/A
A12: 5010 | B12: =VLOOKUP(A12,Tableau1[],'LISTE CATEGORIE'!E:E,FALSE) -> #N/A
A13: 5058 | B13: =VLOOKUP(A13,Tableau1[],'LISTE CATEGORIE'!E:E,FALSE) -> #N/A
A14: 5096 | B14: =VLOOKUP(A14,Tableau1[],'LISTE CATEGORIE'!E:E,FALSE) -> #N/A
A15: 5097 | B15: =VLOOKUP(A15,Tableau1[],'LISTE CATEGORIE'!E:E,FALSE) -> #N/A
... A23: 303 | B23: =VLOOKUP(A23,Tableau1[],'LISTE CATEGORIE'!E:E,FALSE) -> #N/A

Sheet Feuil1
A3: CODE | B3: REFERENCE | C3: DESCRITION | D3: poids par balle | E3: nbre de balles | F3: POIDS TOTAL | G3: PRIX | H3: TOTAL | I3: Colonne1
A4: 5000 | B4: M.C.P | C4: Pantalon en coton pour homme | D4: 65 | E4: 15 | F4: =D4*E4 -> 975 | G4: 1.6 | H4: =F4*G4 -> 1560 | I4: ok
A5: 5001 | B5: M.I.P | C5: Pantalon Jeans Homme | D5: 65 | E5: 15 | F5: =D5*E5 -> 975 | G5: 1.6 | H5: =F5*G5 -> 1560 | I5: ok
A6: 5002 | B6: M.TR.P | C6: Pantalon Tergal Homme | D6: 45 | E6: 15 | F6: =D6*E6 -> 675 | G6: 2 | H6: =F6*G6 -> 1350 | I6: ok
A7: 5007 | B7: B.M.P | C7: Pantalon Mixte Garçon | D7: 40 | E7: 50 | F7: =D7*E7 -> 2000 | G7: 1.6 | H7: =F7*G7 -> 3200 | I7: ok
A8: 5010 | B8: C.C.R MIX | C8: Short et rummage enfants | D8: 45 | E8: 20 | F8: =D8*E8 -> 900 | G8: 3 | H8: =F8*G8 -> 2700 | I8: ok
A9: 5011 | B9: N.R | C9: Rummages nylon | D9: 45 | E9: 9 | F9: =D9*E9 -> 405 | G9: 1.6 | H9: =F9*G9 -> 648 | I9: ok
A10: 5013 | B10: U.W.L | C10: Sous-vêtements Femme | D10: 45 | E10: 3 | F10: =D10*E10 -> 135 | G10: 1.6 | H10: =F10*G10 -> 216 | I10: ok
B11: U.W.M | C11: Sous-vêtements Homme | D11: 45 | E11: 2 | F11: =D11*E11 -> 90 | G11: 1.6 | H11: =F11*G11 -> 144
A12: 5018 | B12: SKA | C12: Écharpes | D12: 45 | E12: 3 | F12: =D12*E12 -> 135 | G12: 1.6 | H12: =F12*G12 -> 216 | I12: ok
A13: 5020 | B13: M.C.SH | C13: Chemises en coton pour hommes | D13: 45 | E13: 5 | F13: =D13*E13 -> 225 | G13: 3 | H13: =F13*G13 -> 675 | I13: ok
A14: 5025 | B14: B.C.SH | C14: Chemise Enfant | D14: 45 | E14: 9 | F14: =D14*E14 -> 405 | G14: 1.3 | H14: =F14*G14 -> 526.5 | I14: ok
A15: 5027 | B15: B.T-SHIRT | C15: T-Shirt enfant | D15: 45 | E15: 3 | F15: =D15*E15 -> 135 | G15: 2 | H15: =F15*G15 -> 270 | I15: ok
A16: 5040 | B16: T.S | C16: Jogging haut et bas | D16: 40 | E16: 40 | F16: =D16*E16 -> 1600 | G16: 1.6 | H16: =F16*G16 -> 2560 | I16: ok
A17: 5041 | B17: CH.T.S | C17: Jogging enfant | D17: 45 | E17: 20 | F17: =D17*E17 -> 900 | G17: 1.6 | H17: =F17*G17 -> 1440 | I17: ok
A18: 5051 | B18: L.O.SH | C18: Short Original Femme | D18: 45 | E18: 7 | F18: =D18*E18 -> 315 | G18: 1.6 | H18: =F18*G18 -> 504 | I18: ok
A19: 5052 | B19: B.O.SH | C19: Short Original Enfants | D19: 45 | E19: 3 | F19: =D19*E19 -> 135 | G19: 1.6 | H19: =F19*G19 -> 216 | I19: ok
A20: 5057 | B20: M.O.SH | C20: Short Original Homme | D20: 45 | E20: 4 | F20: =D20*E20 -> 180 | G20: 2 | H20: =F20*G20 -> 360 | I20: ok
A21: 5066 | B21: WEDDING DRESS | C21: Robe de mariée | D21: 20 | E21: 2 | F21: =D21*E21 -> 40 | G21: 3 | H21: =F21*G21 -> 120
A22: 5070 | B22: H.H.R | C22: Rummages maison | D22: 45 | E22: 15 | F22: =D22*E22 -> 675 | G22: 1.6 | H22: =F22*G22 -> 1080 | I22: ok
A23: 5073 | B23: COVERLY | C23: Coverly | D23: 45 | E23: 5 | F23: =D23*E23 -> 225 | G23: 1.6 | H23: =F23*G23 -> 360 | I23: ok
A24: 5074 | B24: BLA | C24: Couverture | D24: 40 | E24: 30 | F24: =D24*E24 -> 1200 | G24: 1.6 | H24: =F24*G24 -> 1920 | I24: ok
A25: 5075 | B25: L.C | C25: Rideaux en dentelle | D25: 45 | E25: 7 | F25: =D25*E25 -> 315 | G25: 1.6 | H25: =F25*G25 -> 504 | I25: ok
A26: 5076 | B26: TEXTILE | C26: Textile | D26: 45 | E26: 6 | F26: =D26*E26 -> 270 | G26: 0.9 | H26: =F26*G26 -> 243 | I26: ok
A27: 5078 | B27: RIDO | C27: Rido | D27: 45 | E27: 9 | F27: =D27*E27 -> 405 | G27: 0.9 | H27: =F27*G27 -> 364.5 | I27: ok
A28: 5079 | B28: CARPET | C28: Tapis | D28: 45 | E28: 6 | F28: =D28*E28 -> 270 | G28: 1.6 | H28: =F28*G28 -> 432 | I28: ok
A29: 5088 | B29: M.FASH[ON.J | C29: Veste de mode homme | D29: 45 | E29: 15 | F29: =D29*E29 -> 675 | G29: 1.6 | H29: =F29*G29 -> 1080 | I29: ok
A30: 5089 | B30: L.FASHION.J. | C30: Veste de mode dame | D30: 45 | E30: 5 | F30: =D30*E30 -> 225 | G30: 1.6 | H30: =F30*G30 -> 360 | I30: ok
A31: 5090 | B31: L.H.B | C31: Sacs À Main | D31: 100 | E31: 4 | F31: =D31*E31 -> 400 | G31: 1.6 | H31: =F31*G31 -> 640 | I31: ok
A32: 5092 | B32: TRIPBAG | C32: Sacs de voyage (Big-Bag BLEU) | D32: 100 | E32: 1 | F32: =D32*E32 -> 100 | G32: 0.8 | H32: =F32*G32 -> 80 | I32: ok
A33: 5091 | B33: SCHOOL HANDBAGS | C33: Sacs d'écolier | D33: 100 | E33: 1 | F33: =D33*E33 -> 100 | G33: 0.8 | H33: =F33*G33 -> 80
A34: 5093 | B34: BELT | C34: Ceintures | D34: 25 | E34: 3 | F34: =D34*E34 -> 75 | G34: 0.9 | H34: =F34*G34 -> 67.5 | I34: ok
A35: 5096 | B35: M.T-SHIRT | C35: T-Shirt Homme | D35: 45 | E35: 12 | F35: =D35*E35 -> 540 | G35: 3 | H35: =F35*G35 -> 1620 | I35: ok
A36: 5097 | B36: L.T-SHIRT | C36: T-shirts femme | D36: 45 | E36: 4 | F36: =D36*E36 -> 180 | G36: 1.6 | H36: =F36*G36 -> 288 | I36: ok
A37: 5102 | B37: SP.O.SH | C37: Short Sport Original | D37: 45 | E37: 2 | F37: =D37*E37 -> 90 | G37: 3.5 | H37: =F37*G37 -> 315 | I37: ok
A38: 5103 | B38: PANTAKOR SHORTS | C38: pantacourt | D38: 45 | E38: 2 | F38: =D38*E38 -> 90 | G38: 3.5 | H38: =F38*G38 -> 315
A39: 5104 | B39: HANDKERCHIEFS | C39: Mouchoirs | D39: 40 | E39: 1 | F39: =D39*E39 -> 40 | G39: 1.6 | H39: =F39*G39 -> 64 | I39: ok
A40: 5108 | B40: TANK TOP | C40: Débardeur | D40: 45 | E40: 5 | F40: =D40*E40 -> 225 | G40: 1.6 | H40: =F40*G40 -> 360 | I40: ok
A41: 5110 | B41: BODY SUIT | C41: Bodysuit | D41: 45 | E41: 10 | F41: =D41*E41 -> 450 | G41: 1.6 | H41: =F41*G41 -> 720 | I41: ok
A42: 5116 | B42: MINI DRESS | C42: Robe de fille | D42: 45 | E42: 25 | F42: =D42*E42 -> 1125 | G42: 1.6 | H42: =F42*G42 -> 1800
...

Sheet Feuil2
B1: Facture proforma N° | G1: 2408
A2: EURL FRIPERIE AMIRATEX | D2: =TODAY() -> 45706 | F2: SENEGAL | G2: Paiement par virement :
A3: CHEMIN DE LA MOULINE
A4: tél: +33 6 34 23 45 65 | E4: DOMICILIATION BANCAIRE :
A5: http://www-amiratex-france.com | E5: SG BEZIERS VICTOIRE (03232)
A6: Email: habib-frip@hotmail.fr | E6: BIC - Adresse SWIFT : SOGEFRPP
A7: SIRET : 831 270 897 00018 | E7: Bénéficiaire : Friperie Amiratex S.A.R.L
A8: N-TVA : FR 30 831270897 | E8: IBAN : FR76 3000 3032 3200 0200 9579 815
A9: N° EORI : FR 831 270 897 000 18
A10: France
A11: CODE | B11: REFERENCE | C11: DESCRITION | D11: poids par balle | E11: nbre de balles | F11: POIDS TOTAL | G11: PRIX | H11: TOTAL
C12: CREME + GRADE A ÉTÉ
A13: 5002 | B13: M.TR.P | C13: Pantalon Tergal Homme | D13: 40 | E13: 5 | F13: =D13*E13 -> 200 | G13: 2.1 | H13: =F13*G13 -> 420
A14: 5007 | B14: B.M.P | C14: Pantalon Mixte Garçon | D14: 40 | E14: 15 | F14: =D14*E14 -> 600 | G14: 1.7 | H14: =F14*G14 -> 1020
A15: 5015 | B15: B.H | C15: brassière | D15: 80 | E15: 3 | F15: =D15*E15 -> 240 | G15: 1.7 | H15: =F15*G15 -> 408
A16: 5020 | B16: M.C.SH | C16: Chemises en coton pour hommes | D16: 40 | E16: 3 | F16: =D16*E16 -> 120 | G16: 3.1 | H16: =F16*G16 -> 372
A17: 5025 | B17: B.C.SH | C17: Chemise Enfant | D17: 80 | E17: 1 | F17: =D17*E17 -> 80 | G17: 1.4 | H17: =F17*G17 -> 112
A18: 5026 | B18: G.C.BL | C18: Blouse en coton fille | D18: 40 | E18: 14 | F18: =D18*E18 -> 560 | G18: 1.7 | H18: =F18*G18 -> 952
A19: 5027 | B19: B.T-SHIRT | C19: T-Shirt enfant | D19: 40 | E19: 5 | F19: =D19*E19 -> 200 | G19: 2.1 | H19: =F19*G19 -> 420
A20: 5039 | B20: BODY SIS | C20: Body À Manches Courtes | D20: 45 | E20: 10 | F20: =D20*E20 -> 450 | G20: 1.7 | H20: =F20*G20 -> 765
A21: 5041 | B21: CH.T.S | C21: Jogging enfant | D21: 40 | E21: 6 | F21: =D21*E21 -> 240 | G21: 1.7 | H21: =F21*G21 -> 408
A22: 5052 | B22: B.O.SH | C22: Short Original Enfants | D22: 45 | E22: 5 | F22: =D22*E22 -> 225 | G22: 1.7 | H22: =F22*G22 -> 382.5
A23: 5057 | B23: M.O.SH | C23: Short Original Homme | D23: 40 | E23: 2 | F23: =D23*E23 -> 80 | G23: 2.1 | H23: =F23*G23 -> 168
A24: 5058 | B24: L.HAWA 1.P | C24: Pantalon Femme hawai | D24: 55 | E24: 2 | F24: =D24*E24 -> 110 | G24: 3.1 | H24: =F24*G24 -> 341
... A42: 5111 | B42: CARGO PANTS | C42: 5 Pantalons Pocket/ cargo | D42: 40 | E42: 39 | F42: =D42*E42 -> 1560 | G42: 2.1 | H42: =F42*G42 -> 3276
C43: GRADE B ÉTÉ | E43: =SUM(E13:E42) -> 310 | G43: SOUS TOTAL | H43: =SUM(H13:H42) -> 25067.5
A44: 302 | B44: M.TR.P | C44: Pantalon Teregal Homme | D44: 80 | E44: 6 | F44: =D44*E44 -> 480 | G44: 0.65 | H44: =F44*G44 -> 312
A45: 310 | B45: C.C.R | C45: Rummages Bébé Coton | D45: 45 | E45: 40 | F45: =D45*E45 -> 1800 | G45: 0.85 | H45: =F45*G45 -> 1530
A46: 313 | B46: U.W | C46: Sous-vêtements | D46: 40 | E46: 5 | F46: =D46*E46 -> 200 | G46: 0.75 | H46: =F46*G46 -> 150
A47: 320 | B47: M.C.SH | C47: Chemises en coton hommes | D47: 40 | E47: 5 | F47: =D47*E47 -> 200 | G47: 0.75 | H47: =F47*G47 -> 150
A48: 328 | B48: POLO HOOD | C48: Polo à capuches | D48: 40 | E48: 48 | F48: =D48*E48 -> 1920 | G48: 1.25 | H48: =F48*G48 -> 2400
A49: 337 | B49: B.POLO | C49: Polo Garçon | D49: 55 | E49: 58 | F49: =D49*E49 -> 3190 | G49: 0.7 | H49: =F49*G49 -> 2233
A50: 357 | B50: B.T-SHIRT | C50: T-Shirt Garçon | D50: 45 | E50: 2 | F50: =D50*E50 -> 90 | G50: 0.75 | H50: =F50*G50 -> 67.5
A51: 358 | B51: M.T-SHIRT | C51: T-Shirt Homme | D51: 45 | E51: 10 | F51: =D51*E51 -> 450 | G51: 0.85 | H51: =F51*G51 -> 382.5
A52: 360 | B52: L.C.DR | C52: Robe en coton pour femme | D52: 45 | E52: 15 | F52: =D52*E52 -> 675 | G52: 0.75 | H52: =F52*G52 -> 506.25
A53: 361 | B53: L.C.SK | C53: Jupe en coton pour femme | D53: 45 | E53: 15 | F53: =D53*E53 -> 675 | G53: 0.75 | H53: =F53*G53 -> 506.25
C54: CHAUSSURES ET ACCESSOIRES | E54: =SUM(E44:E53) -> 204 | G54: SOUS TOTAL | H54: =SUM(H44:H53) -> 8237.5
A55: 405 | B55: PLASTIC SHOES | C55: Chaussures en plastique | D55: 25 | E55: 5 | F55: =D55*E55 -> 125 | G55: 2.6 | H55: =F55*G55 -> 325
A56: 435 | B56: FOAMSHOES | C56: Chaussures en mousse | D56: 10 | E56: 13 | F56: =D56*E56 -> 130 | G56: 2.6 | H56: =F56*G56 -> 338
A57: 865 | B57: BRIC & BRAC | C57: Bric & Brac | D57: 20 | E57: 60 | F57: =D57*E57 -> 1200 | G57: 0.7 | H57: =F57*G57 -> 840
...

Sheet Feuil3
A1: CREME + GRADE A ÉTÉ | B1: CREAM + SUMMER GRADE A
A2: Pantalon en coton pour homme | B2: Men's cotton pants
A3: Pantalon Jeans Homme | B3: Men's jeans pants
A4: Pantalon Tergal Homme | B4: Men's tergal pants
A5: Pantalon mixte femme | B5: Women's mixed pants
A6: Vizoon + Femme + Enfants+ leggings | B6: Vizoon + Women + Children + leggings
A7: Pantalon Mixte Garçon | B7: Boy's mixed pants
A8: Pantalons enfants | B8: Children's pants
A9: vêtements de travail | B9: work clothes
A10: Short et rummage enfants | B10: Children's shorts and rummage
A11: Rummages nylon | B11: Nylon Rummages
A12: Mayo | B12: Mayo
... A105: Chaussures de sécurité | B105: Safety Shoes

Sheet Feuil2 (2)
B1: Facture proforma N° | G1: 2408
A2: EURL FRIPERIE AMIRATEX | D2: =TODAY() -> 45706 | F2: SENEGAL | G2: Paiement par virement :
A3: CHEMIN DE LA MOULINE
A4: tél: +33 6 34 23 45 65 | E4: DOMICILIATION BANCAIRE :
A5: http://www-amiratex-france.com | E5: SG BEZIERS VICTOIRE (03232)
A6: Email: habib-frip@hotmail.fr | E6: BIC - Adresse SWIFT : SOGEFRPP
A7: SIRET : 831 270 897 00018 | E7: Bénéficiaire : Friperie Amiratex S.A.R.L
A8: N-TVA : FR 30 831270897 | E8: IBAN : FR76 3000 3032 3200 0200 9579 815
A9: N° EORI : FR 831 270 897 000 18
A10: France
A11: CODE | B11: REFERENCE | C11: DESCRITION | D11: poids par balle | E11: nbre de balles | F11: POIDS TOTAL | G11: PRIX | H11: TOTAL
C12: CREME + GRADE A ÉTÉ
A13: 5002 | B13: M.TR.P | C13: Pantalon Tergal Homme | D13: 40 | E13: 5 | F13: =D13*E13 -> 200 | G13: 2 | H13: =F13*G13 -> 400 | J13: =G13-$K$13 -> 1.9 | K13: 0.1
A14: 5007 | B14: B.M.P | C14: Pantalon Mixte Garçon | D14: 40 | E14: 15 | F14: =D14*E14 -> 600 | G14: 1.6 | H14: =F14*G14 -> 960 | J14: =G14-$K$13 -> 1.5
A15: 5015 | B15: B.H | C15: brassière | D15: 80 | E15: 3 | F15: =D15*E15 -> 240 | G15: 1.6 | H15: =F15*G15 -> 384 | J15: =G15-$K$13 -> 1.5
A16: 5020 | B16: M.C.SH | C16: Chemises en coton pour hommes | D16: 40 | E16: 3 | F16: =D16*E16 -> 120 | G16: 3 | H16: =F16*G16 -> 360 | J16: =G16-$K$13 -> 2.9
A17: 5025 | B17: B.C.SH | C17: Chemise Enfant | D17: 80 | E17: 1 | F17: =D17*E17 -> 80 | G17: 1.3 | H17: =F17*G17 -> 104 | J17: =G17-$K$13 -> 1.2
A18: 5026 | B18: G.C.BL | C18: Blouse en coton fille | D18: 40 | E18: 14 | F18: =D18*E18 -> 560 | G18: 1.6 | H18: =F18*G18 -> 896 | J18: =G18-$K$13 -> 1.5
A19: 5027 | B19: B.T-SHIRT | C19: T-Shirt enfant | D19: 40 | E19: 5 | F19: =D19*E19 -> 200 | G19: 2 | H19: =F19*G19 -> 400 | J19: =G19-$K$13 -> 1.9
A20: 5039 | B20: BODY SIS | C20: Body À Manches Courtes | D20: 45 | E20: 10 | F20: =D20*E20 -> 450 | G20: 1.6 | H20: =F20*G20 -> 720 | J20: =G20-$K$13 -> 1.5
A21: 5041 | B21: CH.T.S | C21: Jogging enfant | D21: 40 | E21: 6 | F21: =D21*E21 -> 240 | G21: 1.6 | H21: =F21*G21 -> 384 | J21: =G21-$K$13 -> 1.5
A22: 5052 | B22: B.O.SH | C22: Short Original Enfants | D22: 45 | E22: 5 | F22: =D22*E22 -> 225 | G22: 1.6 | H22: =F22*G22 -> 360 | J22: =G22-$K$13 -> 1.5
A23: 5057 | B23: M.O.SH | C23: Short Original Homme | D23: 40 | E23: 2 | F23: =D23*E23 -> 80 | G23: 2 | H23: =F23*G23 -> 160 | J23: =G23-$K$13 -> 1.9
A24: 5058 | B24: L.HAWA 1.P | C24: Pantalon Femme hawai | D24: 55 | E24: 2 | F24: =D24*E24 -> 110 | G24: 3 | H24: =F24*G24 -> 330 | J24: =G24-$K$13 -> 2.9
A25: 5060 | B25: L.C.DR | C25: Robe en coton pour femme | D25: 40 | E25: 15 | F25: =D25*E25 -> 600 | G25: 3 | H25: =F25*G25 -> 1800 | J25: =G25-$K$13 -> 2.9
... A42: 5111 | B42: CARGO PANTS | C42: 5 Pantalons Pocket/ cargo | D42: 40 | E42: 39 | F42: =D42*E42 -> 1560 | G42: 2 | H42: =F42*G42 -> 3120 | J42: =G42-$K$13 -> 1.9
C43: GRADE B ÉTÉ | E43: =SUM(E13:E42) -> 310 | G43: SOUS TOTAL | H43: =SUM(H13:H42) -> 23767
A44: 302 | B44: M.TR.P | C44: Pantalon Teregal Homme | D44: 80 | E44: 6 | F44: =D44*E44 -> 480 | G44: 0.6 | H44: =F44*G44 -> 288 | J44: =G44-0.05 -> 0.55
A45: 310 | B45: C.C.R | C45: Rummages Bébé Coton | D45: 45 | E45: 40 | F45: =D45*E45 -> 1800 | G45: 0.8 | H45: =F45*G45 -> 1440 | J45: =G45-0.05 -> 0.75
A46: 313 | B46: U.W | C46: Sous-vêtements | D46: 40 | E46: 5 | F46: =D46*E46 -> 200 | G46: 0.7 | H46: =F46*G46 -> 140 | J46: =G46-0.05 -> 0.65
A47: 320 | B47: M.C.SH | C47: Chemises en coton hommes | D47: 40 | E47: 5 | F47: =D47*E47 -> 200 | G47: 0.7 | H47: =F47*G47 -> 140 | J47: =G47-0.05 -> 0.65
A48: 328 | B48: POLO HOOD | C48: Polo à capuches | D48: 40 | E48: 48 | F48: =D48*E48 -> 1920 | G48: 1.2 | H48: =F48*G48 -> 2304 | J48: =G48-0.05 -> 1.15
A49: 337 | B49: B.POLO | C49: Polo Garçon | D49: 55 | E49: 58 | F49: =D49*E49 -> 3190 | G49: 0.65 | H49: =F49*G49 -> 2073.5 | J49: =G49-0.05 -> 0.6
A50: 357 | B50: B.T-SHIRT | C50: T-Shirt Garçon | D50: 45 | E50: 2 | F50: =D50*E50 -> 90 | G50: 0.7 | H50: =F50*G50 -> 63 | J50: =G50-0.05 -> 0.65
A51: 358 | B51: M.T-SHIRT | C51: T-Shirt Homme | D51: 45 | E51: 10 | F51: =D51*E51 -> 450 | G51: 0.8 | H51: =F51*G51 -> 360 | J51: =G51-0.05 -> 0.75
A52: 360 | B52: L.C.DR | C52: Robe en coton pour femme | D52: 45 | E52: 15 | F52: =D52*E52 -> 675 | G52: 0.7 | H52: =F52*G52 -> 472.5 | J52: =G52-0.05 -> 0.65
A53: 361 | B53: L.C.SK | C53: Jupe en coton pour femme | D53: 45 | E53: 15 | F53: =D53*E53 -> 675 | G53: 0.7 | H53: =F53*G53 -> 472.5 | J53: =G53-0.05 -> 0.65
C54: CHAUSSURES ET ACCESSOIRES | E54: =SUM(E44:E53) -> 204 | G54: SOUS TOTAL | H54: =SUM(H44:H53) -> 7753.5
A55: 405 | B55: PLASTIC SHOES | C55: Chaussures en plastique | D55: 25 | E55: 5 | F55: =D55*E55 -> 125 | G55: 2.5 | H55: =F55*G55 -> 312.5
A56: 435 | B56: FOAMSHOES | C56: Chaussures en mousse | D56: 10 | E56: 13 | F56: =D56*E56 -> 130 | G56: 2.5 | H56: =F56*G56 -> 325
...

Sheet Feuil4
C1: Catalogue Amiratex PR
A2: CODE | B2: REFERENCE | C2: DESCRITION | D2: poids par balle | E2: nbre de balles | F2: POIDS TOTAL
C3: CREME + GRADE A ÉTÉ
A4: 5000 | B4: M.C.P | C4: Pantalon en coton pour homme | D4: 40 | E4: 5 | F4: =D4*E4 -> 200
A5: 5001 | B5: M.I.P | C5: Pantalon Jeans Homme | D5: 65 | E5: 6 | F5: =D5*E5 -> 390
A6: 5002 | B6: M.TR.P | C6: Pantalon Tergal Homme | D6: 40 | E6: 5 | F6: =D6*E6 -> 200
A7: 5003 | B7: L.M.P | C7: Pantalon mixte femme | D7: 40 | E7: 35 | F7: =D7*E7 -> 1400
A8: 5006 | B8: VIZOON | C8: Vizoon + Femme + Enfants+ leggings | D8: 45 | E8: 10 | F8: =D8*E8 -> 450
A9: 5007 | B9: B.M.P | C9: Pantalon Mixte Garçon | D9: 40 | E9: 15 | F9: =D9*E9 -> 600
A10: 5008 | B10: CH.P | C10: Pantalons enfants | D10: 40 | E10: 3 | F10: =D10*E10 -> 120
A11: 5009 | B11: T.T | C11: vêtements de travail | D11: 55 | E11: 8 | F11: =D11*E11 -> 440
A12: 5010 | B12: C.C.R MIX | C12: Short et rummage enfants | D12: 45 | E12: 15 | F12: =D12*E12 -> 675
A13: 5011 | B13: N.R | C13: Rummages nylon | D13: 45 | E13: 4 | F13: =D13*E13 -> 180
A14: 5012 | B14: MAYO | C14: Mayo | D14: 40 | E14: 10 | F14: =D14*E14 -> 400
A15: 5013 | B15: U.W | C15: Sous-vêtements Femme | D15: 40 | E15: 2 | F15: =D15*E15 -> 80
... A66: 400 | B66: SHOESN.o 1 | C66: Chaussures cat. 1 | D66: 22 | E66: 70 | F66: =D66*E66 -> 1540
C67: CREME+ GRADE A HIVER
A68: 514 | B68: WOOLCAPS | C68: Casquettes en laine | D68: 80 | E68: 2 | F68: =D68*E68 -> 160
A69: 580 | B69: M.ZIP | C69: Homme Fermeture Éclair | D69: 80 | E69: 10 | F69: =D69*E69 -> 800
C70: GRADE B ÉTÉ
A71: 301 | B71: M.J.P | C71: Pantalon Jeans Homme | D71: 45 | E71: 20 | F71: =D71*E71 -> 900
A72: 302 | B72: M.TR.P | C72: Pantalon Teregal Homme | D72: 80 | E72: 6 | F72: =D72*E72 -> 480
A73: 303 | B73: L.M.P | C73: Pantalon mixte dame | D73: 45 | E73: 50 | F73: =D73*E73 -> 2250
A74: 310 | B74: C.C.R | C74: Rummages Bébé Coton | D74: 45 | E74: 40 | F74: =D74*E74 -> 1800
A75: 313 | B75: U.W | C75: Sous-vêtements | D75: 40 | E75: 5 | F75: =D75*E75 -> 200
A76: 320 | B76: M.C.SH | C76: Chemises en coton hommes | D76: 40 | E76: 5 | F76: =D76*E76 -> 200
A77: 323 | B77: L.C. BL | C77: Blouse coton Femme | D77: 55 | E77: 15 | F77: =D77*E77 -> 825
A78: 328 | B78: POLO HOOD | C78: Polo à capuches | D78: 40 | E78: 48 | F78: =D78*E78 -> 1920
A79: 337 | B79: B.POLO | C79: Polo Garçon | D79: 55 | E79: 58 | F79: =D79*E79 -> 3190
A80: 340 | B80: T.S | C80: Jogging | D80: 40 | E80: 58 | F80: =D80*E80 -> 2320
A81: 342 | B81: T.S VELVET | C81: Pantalon en velours | D81: 40 | E81: 5 | F81: =D81*E81 -> 200
A82: 346 | B82: T-SHIRT | C82: T-shirt | D82: 45 | E82: 10 | F82: =D82*E82 -> 450
... A94: 910 | B94: SHOESN.o2 | C94: Chaussures cat. 2 | D94: 22 | E94: 142 | F94: =D94*E94 -> 3124
C95: GRADE B HIVER
A96: 607 | B96: L.CORDEROY.P | C96: Pantalon Lady Corderoy | D96: 80 | E96: 10 | F96: =D96*E96 -> 800
A97: 616 | B97: C.M.R | C97: Rummage Medium Enfant | D97: 80 | E97: 28 | F97: =D97*E97 -> 2240
A98: 640 | B98: B.B.W. | C98: Rummage bébé | D98: 55 | E98: 40 | F98: =D98*E98 -> 2200
A99: 649 | B99: C.C.R MEDIUM | C99: Rummage Medium Enfant | D99: 80 | E99: 42 | F99: =D99*E99 -> 3360
A100: 680 | B100: M.ZIP | C100: Homme Fermeture Éclair | D100: 80 | E100: 10 | F100: =D100*E100 -> 800
C101: CHAUSSURES ET ACCESSOIRES
...

Sheet LISTE CATEGORIE (2)
E2: catalogue avec + 10 cts | G2: CODE REFERENCE DESCRIPTION weight per ball number of balls TOTAL WEIGHT TOTAL PRICE
D3: Catalogue Amiratex PR
B5: CODE | C5: REFERENCE | D5: DESCRITION | E5: WEIGHT PER BALL( kg) | F5: NUMBER OF BALLS | G5: TOTAL WEIGHT | H5: PRICE | I5: TOTAL | J5: Colonne1
D6: CREAM + SUMMER GRADE A
B7: 5000 | C7: M.C.P | D7: Men's cotton pants | E7: 40 | F7: 5 | G7: =E7*F7 -> 200 | H7: 1.6 | I7: =G7*H7 -> 320 | J7: ok | K7: =H7-0.1 -> 1.5
B8: 5001 | C8: M.I.P | D8: Men's jeans pants | E8: 65 | F8: 6 | G8: =E8*F8 -> 390 | H8: 1.6 | I8: =G8*H8 -> 624 | J8: ok | K8: =H8-0.1 -> 1.5
B9: 5002 | C9: M.TR.P | D9: Men's tergal pants | E9: 40 | F9: 5 | G9: =E9*F9 -> 200 | H9: 2 | I9: =G9*H9 -> 400 | J9: ok | K9: =H9-0.1 -> 1.9
B10: 5003 | C10: L.M.P | D10: Women's mixed pants | E10: 40 | F10: 35 | G10: =E10*F10 -> 1400 | H10: 1.6 | I10: =G10*H10 -> 2240 | K10: =H10-0.1 -> 1.5
B11: 5006 | C11: VIZOON | D11: Vizoon + Women + Children + leggings | E11: 45 | F11: 10 | G11: =E11*F11 -> 450 | H11: 1.6 | I11: =G11*H11 -> 720 | K11: =H11-0.1 -> 1.5
B12: 5007 | C12: B.M.P | D12: Boy's mixed pants | E12: 40 | F12: 15 | G12: =E12*F12 -> 600 | H12: 1.6 | I12: =G12*H12 -> 960 | J12: ok | K12: =H12-0.1 -> 1.5
B13: 5008 | C13: CH.P | D13: Children's pants | E13: 40 | F13: 3 | G13: =E13*F13 -> 120 | H13: 1.6 | I13: =G13*H13 -> 192 | K13: =H13-0.1 -> 1.5
B14: 5009 | C14: T.T | D14: work clothes | E14: 55 | F14: 8 | G14: =E14*F14 -> 440 | H14: 1.3 | I14: =G14*H14 -> 572 | K14: =H14-0.1 -> 1.2
B15: 5010 | C15: C.C.R MIX | D15: Children's shorts and rummage | E15: 45 | F15: 15 | G15: =E15*F15 -> 675 | H15: 3 | I15: =G15*H15 -> 2025 | J15: ok | K15: =H15-0.1 -> 2.9
B16: 5011 | C16: N.R | D16: Nylon Rummages | E16: 45 | F16: 4 | G16: =E16*F16 -> 180 | H16: 1.6 | I16: =G16*H16 -> 288 | J16: ok | K16: =H16-0.1 -> 1.5
B17: 5012 | C17: MAYO | D17: Mayo | E17: 40 | F17: 10 | G17: =E17*F17 -> 400 | H17: 1.6 | I17: =G17*H17 -> 640 | K17: =H17-0.1 -> 1.5
B18: 5013 | C18: U.W | D18: Women's underwear | E18: 40 | F18: 2 | G18: =E18*F18 -> 80 | H18: 1.6 | I18: =G18*H18 -> 128 | J18: ok | K18: =H18-0.1 -> 1.5
B19: 5014 | C19: U.W | D19: Underwear | E19: 55 | F19: 4 | G19: =E19*F19 -> 220 | H19: 1.6 | I19: =G19*H19 -> 352 | K19: =H19-0.1 -> 1.5
B20: 5015 | C20: B.H | D20: brassiere | E20: 80 | F20: 3 | G20: =E20*F20 -> 240 | H20: 1.6 | I20: =G20*H20 -> 384 | K20: =H20-0.1 -> 1.5
B21: 5017 | C21: L.N.DR | D21: Women's nightgowns | E21: 45 | F21: 1 | G21: =E21*F21 -> 45 | H21: 1.6 | I21: =G21*H21 -> 72 | K21: =H21-0.1 -> 1.5
B22: 5018 | C22: SKA | D22: Scarves | E22: 40 | F22: 10 | G22: =E22*F22 -> 400 | H22: 1.6 | I22: =G22*H22 -> 640 | J22: ok | K22: =H22-0.1 -> 1.5
B23: 5020 | C23: M.C.SH | D23: Men's cotton shirts | E23: 40 | F23: 3 | G23: =E23*F23 -> 120 | H23: 3 | I23: =G23*H23 -> 360 | J23: ok | K23: =H23-0.1 -> 2.9
B24: 5024 | C24: L.S.BL | D24: Women's silk blouse | E24: 40 | F24: 5 | G24: =E24*F24 -> 200 | H24: 1.6 | I24: =G24*H24 -> 320 | K24: =H24-0.1 -> 1.5
B25: 5025 | C25: B.C.SH | D25: Children's shirt | E25: 80 | F25: 1 | G25: =E25*F25 -> 80 | H25: 1.3 | I25: =G25*H25 -> 104 | J25: ok | K25: =H25-0.1 -> 1.2
B26: 5026 | C26: G.C.BL | D26: Girl's cotton blouse | E26: 40 | F26: 14 | G26: =E26*F26 -> 560 | H26: 1.6 | I26: =G26*H26 -> 896 | K26: =H26-0.1 -> 1.5
B27: 5027 | C27: B.T-SHIRT | D27: Children's T-Shirt | E27: 40 | F27: 5 | G27: =E27*F27 -> 200 | H27: 2 | I27: =G27*H27 -> 400 | J27: ok | K27: =H27-0.1 -> 1.9
B28: 5036 | C28: BODY SWEAT | D28: Body Sweat | E28: 55 | F28: 2 | G28: =E28*F28 -> 110 | H28: 2 | I28: =G28*H28 -> 220 | K28: =H28-0.1 -> 1.9
B29: 5039 | C29: BODY SIS | D29: Short Sleeve Body | E29: 45 | F29: 10 | G29: =E29*F29 -> 450 | H29: 1.6 | I29: =G29*H29 -> 720 | K29: =H29-0.1 -> 1.5
B30: 5040 | C30: T.S | D30: Jogging top and bottom | E30: 45 | F30: 10 | G30: =E30*F30 -> 450 | H30: 1.6 | I30: =G30*H30 -> 720 | J30: ok | K30: =H30-0.1 -> 1.5
B31: 5041 | C31: CH.T.S | D31: Children's jogging | E31: 40 | F31: 6 | G31: =E31*F31 -> 240 | H31: 1.6 | I31: =G31*H31 -> 384 | J31: ok | K31: =H31-0.1 -> 1.5
B32: 5043 | C32: JOGGING | D32: Jogging | E32: 40 | F32: 4 | G32: =E32*F32 -> 160 | H32: 1.6 | I32: =G32*H32 -> 256 | K32: =H32-0.1 -> 1.5
B33: 5051 | C33: L.O.SH | D33: Original Women's shorts | E33: 45 | F33: 1 | G33: =E33*F33 -> 45 | H33: 1.6 | I33: =G33*H33 -> 72 | J33: ok | K33: =H33-0.1 -> 1.5
B34: 5052 | C34: B.O.SH | D34: Original Children's shorts | E34: 45 | F34: 5 | G34: =E34*F34 -> 225 | H34: 1.6 | I34: =G34*H34 -> 360 | J34: ok | K34: =H34-0.1 -> 1.5
B35: 5057 | C35: M.O.SH | D35: Original Men's shorts | E35: 40 | F35: 2 | G35: =E35*F35 -> 80 | H35: 2 | I35: =G35*H35 -> 160 | J35: ok | K35: =H35-0.1 -> 1.9
B36: 5058 | C36: L.HAWA 1.P | D36: Women's hawai pants | E36: 55 | F36: 2 | G36: =E36*F36 -> 110 | H36: 3 | I36: =G36*H36 -> 330 | K36: =H36-0.1 -> 2.9
B37: 5060 | C37: L.C.DR | D37: Women's cotton dress | E37: 40 | F37: 15 | G37: =E37*F37 -> 600 | H37: 3 | I37: =G37*H37 -> 1800 | K37: =H37-0.1 -> 2.9
B38: 5061 | C38: L.C.SK | D38: Women's cotton skirt | E38: 80 | F38: 5 | G38: =E38*F38 -> 400 | H38: 1.3 | I38: =G38*H38 -> 520 | K38: =H38-0.1 -> 1.2
B39: 5062 | C39: G.C.SK+DR | D39: Girl's cotton skirts + dresses | E39: 45 | F39: 15 | G39: =E39*F39 -> 675 | H39: 1.6 | I39: =G39*H39 -> 1080 | K39: =H39-0.1 -> 1.5
B40: 5070 | C40: H.H.R | D40: Home Rummages | E40: 40 | F40: 70 | G40: =E40*F40 -> 2800 | H40: 1.6 | I40: =G40*H40 -> 4480 | J40: ok | K40: =H40-0.1 -> 1.5
B41: 5073 | C41: COVERLY | D41: Coverly | E41: 55 | F41: 5 | G41: =E41*F41 -> 275 | H41: 1.6 | I41: =G41*H41 -> 440 | J41: ok | K41: =H41-0.1 -> 1.5
B42: 5074 | C42: BLA | D42: Blanket | E42: 40 | F42: 12 | G42: =E42*F42 -> 480 | H42: 1.6 | I42: =G42*H42 -> 768 | J42: ok | K42: =H42-0.1 -> 1.5
...
